Workbook
Name AUFTEILER_TPL_V2: 'Verkauf Cashflow'!$A$1
Name AUFTEILER_TPL_LAYOUT: 2

Sheet BESICHTIGUNG
A1: CHECKLISTE BESICHTIGUNG
A2: Datum Besichtigung
A3: Lead Herkunft
A5: EINKAUF
A6: Anschrift
A7: Wohnfläche in m²
A8: Baujahr
A9: Wohneinheiten im Haus
A10: Hausgeld pro Monat | B10: 0
A11: Rücklagen des Hauses | B11: 0
A12: Gewinn | B12: 0.3
A13: Inseratspreis
A14: Inseratspreis pro m² | B14: =B13/B7
A15: Besonderheiten Haus / Erster Eindruck Umgebung | B15: Text
A17: ZUSTAND (MIT BILDER DOKUMENTIEREN!)
A18: Dach | B18: Zustand?
A19: Fassade | B19: Zustand?
A20: Fenster | B20: Zustand?
A21: Stellplatz / Garage | B21: Vorhanden?
A22: Heizung | B22: Art? Baujahr?
A23: Elektrik | B23: Zustand?
A25: VERKÄUFER
A26: Wer ist der Eigentümer? | B26: Text
A27: Warum wird verkauft? | B27: Text
A28: Schmerzgrenze Preis?
A30: MIETSITUATION
A31: Wie viele Einheiten sind vermietet?
A32: Wie viele Einheiten stehen leer?
A33: IST Jahresnettokaltmiete? (JNKM)
A34: Kappungsgrenze? | B34: 0
A35: Wann waren die letzten Mieterhöhungen?
A36: SOLL Jahresnettokaltmiete? (JNKM)
A39: SONSTIGE NOTIZEN
A40: Text

Sheet KALKU
H2: HINWEISE ZUR KALKULATION / NOTIZEN
H3: =IF(AND(C13<250)," Wir empfehlen keine MFHs unter 250m²","")
H4: =IF(C14<1950," Achtung, Hinweis zum Baujahr!","")
B5: DATEN EINGABE → | C5: Wert eingeben | H5: =IF(AND(C15>1,C15<6)," Wir empfehlen Mehrfamilienhäuser ab 6 Einheiten","")
H6: =IF(((MIETER!L28/MIETER!M6)<0.6)," Achtung, Sehr geringe Miete!","")
B7: WERT WIRD BERECHNET → | C7: Wert wird berechnet | H7: =IF(J29>(600*C13)," Achtung, erhöhter Renovierungsaufwand!","")
B10: 1. EINKAUF | H10: 4. VORKALKULATION DER IMMOBILIE
B11: LINK ZU OBJEKTORDNER | C11: Drive Ordner | H11: PORTAL | I11: =" PORTALSPREIS (für ⌀"&TEXT(C13/C15,"#,##")&"m² Wohnfläche)" | K11: AUF- / ABSCHLÄGE | O11: VERKAUFSPREIS
B12: ANSCHRIFT | C12: =BESICHTIGUNG!B6 | K12: -0.05 | N12: =F41
B13: WOHNFLAECHE | C13: =BESICHTIGUNG!B7 | H13: Homeday Atlas | I13: 2800 | K13: =I13*(1+$K$12) | N13: =K13*(1+$F$41) | O13: =N13*$C$13
B14: BAUJAHR | C14: =BESICHTIGUNG!B8 | H14: IS24 Preisatlas | I14: 2900 | K14: =I14*(1+$K$12) | N14: =K14*(1+$F$41) | O14: =N14*$C$13
B15: WOHNEINHEITEN IM HAUS | C15: =BESICHTIGUNG!B9 | H15: Pricehubble / Check24 | I15: 2900 | K15: =I15*(1+$K$12) | N15: =K15*(1+$F$41) | O15: =N15*$C$13
B16: HAUSGELD PRO MONAT | C16: =1.5*C13 | H16: InterHyp | I16: 2700 | K16: =I16*(1+$K$12) | N16: =K16*(1+$F$41) | O16: =N16*$C$13
B17: RÜCKLAGEN DES HAUSES | C17: 0 | H17: Wohnungmarktbericht | I17: 2000 | K17: =IF(I17>0,I17*(1+$K$12),"") | N17: =IF(K17<>"",K17*(1+$F$41),"") | O17: =IF(N17<>"",N17*$C$13,"")
B18: GEWINN | C18: 0.35 | H18: ⌀ PORTALE | I18: =AVERAGE(I13:I17) | K18: =AVERAGE(K13:K17) | N18: =AVERAGE(N13:N17) | O18: =AVERAGE(O13:O17)
B19: SCHMERZGRENZE | C19: =BESICHTIGUNG!B28
B20: PREIS PRO m² | C20: =IFERROR(C19/C13,"") | H20: 5. BETEILIGUNG INVESTOR / DEALTRADER | M20: 9. FINANZIERUNG
B21: ZINSEN (variabel) | C21: 0.06 | D21: ZINSBINDUNG | F21: 12 | H21: GEWINNBETEILIGUNG DEALTRADER (%) | I21: 0 | J21: =I21*J40 | M21: GIK | P21: =J39
B22: EINMALKOSTEN FINANZIERUNG | C22: 0 | D22: =P24*C22 | H22: GEWINNBETEILIGUNG INVESTOR (%) | I22: 0 | J22: =I22*J40 | M22: - EK | P22: 0
B23: ZINS (B&H) | C23: 0.04 | H23: SONSTIGE BETEILIGUNG | I23: 0 | J23: 0 | M23: - Darlehen Investor | O23: 0 | P23: 0
B24: TILGUNG (B&H) | C24: 0.02 | H24: = RESTGEWINN HÄNDLER | I24: =J40-J21-J22 | M24: = Darlehen Bank | P24: =P21-P22-P23
B26: 2. NEBENKOSTENRECHNER | H26: 6. KOSTEN | M26: 10. WORST-CASE RECHNER (B&H)
B27: BUNDESLAND | D27: Nordrhein-Westfalen | H27: - FINANZIERUNGSKOSTEN | I27: =J27/C13 | J27: =(P23*(O23*(F21/12)))+(P24*(C21*(F21/12)))+D22 | M27: ZINSKOSTEN (pro Jahr B&H) | P27: =P24*(C23+C24)
B28: NOTAR- UND GRUNDBUCHKOSTEN | E28: =VLOOKUP(D27,NK!A2:C17,2,FALSE()) | F28: =E28*P37 | H28: =" - HAUSGELD ("&F21&" MONATE)" | I28: =J28/C13 | J28: =(C16*F21) | M28: HAUSGELD (pro Jahr B&H) | P28: =C16*12
B29: GRUNDERWERBSTEUER | E29: =VLOOKUP(D27,NK!A2:C17,3,FALSE()) | F29: =E29*P37 | H29: - AUFWERTUNGSKOSTEN (RENO BLATT) | I29: =J29/C13 | J29: =RENO!O8 | M29: JAHRESNETTOKALTMIETE SOLL | P29: =MIETER!N31
B30: MAKLERPROVISION | D30: 0.03 | E30: =D30*1.19 | F30: =E30*P37 | H30: - KAUFNEBENKOSTEN | I30: =J30/C13 | J30: =(J39-J27-J28-J29-J31)*(E31/(1+E31)) | M30: = CASHFLOW PRO JAHR | P30: =P29-P27-P28
B31: KAUFNEBENKOSTEN = | E31: =SUM(E28:E30) | F31: =SUM(F28:F30) | H31: =" - MIETEINNAHMEN IST ("&F21&" MONATE)" | J31: =(MIETER!J31*-1)*(F21/12) | M31: => RENDITE (JNKM zu KP+NK) Mietspiegel | P31: =P29/(P37+J30)
H32: = GESAMTKOSTEN | I32: =SUM(I27:I30) | J32: =SUM(J27:J31) | M32: => RENDITE (JNKM zu GIK) Modernisierung | P32: =MIETER!R31/J39
B34: 3. AUF-/ABSCHLAG | F34: =YEAR(TODAY()) | H34: 7. GEWINN & GIK | M34: 8. ANGEBOT
B35: ART DER HEIZUNG | C35: Zentral | E35: Elektro | F35: =IF(OR(E35="Öl", E35="Elektro"), -0.05, IF(E35="Gas", 0, IF(OR(E35="Pellet", E35="Wärmepumpe"), 0.05, ""))) | G35: =F34-E36 | H35: =" VERKAUFSPREIS aus VORKALKULATION (inkl. "&TEXT(C17-(20*C13),"#,##0 €")&" Rücklagen)" | I35: =J35/C13 | J35: =O18+C17-(50*C13) | M35: SCHMERZGRENZE | O35: =P35/C13 | P35: =C19
B36: BAUJAHR HEIZUNG | E36: 2024 | F36: =IF(ISBLANK(E36), 0, MAX(MIN(0.03 - 0.003 * (F34 - E36), 0.03), -0.09))
B37: FASSADE WIRD / IST GEDÄMMT? | E37: Ja | F37: =IF(E37="Nein",-0.04,0.04) | H37: VERKAUFSPREIS aus VERKAUFSMATRIX (Detailbetrachtung aller Wohnungen) | I37: =J37/C13 | J37: =VERKAUFSMATRIX!Y28 | M37: DEIN ANGEBOTSPREIS | O37: =P37/C13 | P37: =J39-J32
B38: ZÄHLERSCHRANK WIRD / WURDE ERNEUERT? | E38: 2024 | F38: =IF(ISBLANK(E38), 0, MAX(MIN(0.01 - 0.001 * (F34 - E38), 0.01), -0.02))
B39: TREPPENHAUS WIRD / WURDE RENOVIERT? | E39: Ja | F39: =IF(E39="Nein",-0.02,0.02) | H39: - GESAMTINVESTITIONSKOSTEN | I39: =J39/C13 | J39: =J37/(1+C18)
B40: INDIVIDUELLER AUF-/ABSCHLAG | F40: 0 | H40: =" = GEWINN "&TEXT(C18,"0%") | I40: =J40/C13 | J40: =J39*C18 | M40: DIFFERENZ (€) | O40: =P40/C13 | P40: =P37-P35
B41: AUF-/ABSCHLAG GESAMT = | F41: =SUM(F35:F40) | M41: DIFFERENZ (%) | O41: =IFERROR(1-(P37/P35),"")

Sheet RENO
B2: AUFWERTUNGSKALKULATION
B4: Anschrift | F4: =KALKU!C12 | K4: ="Kalkulierte Reno Kosten inkl. "&TEXT(I6,"0%")&" Puffer (Netto)" | O4: =P106*(1+I6) | P4: =IF(OR(F5=0,F5=""),"",O4/F5)
B5: Wohnfläche | F5: =KALKU!C13 | I5: 27
B6: Baujahr | F6: =KALKU!C14 | I6: 0.1 | K6: ="Kalkulierte Reno Kosten inkl. "&TEXT(I6,"0%")&" Puffer (Brutto)" | O6: =O4*(1+I7) | P6: =IF(OR(F5=0,F5=""),"",O6/F5)
B7: Marge Handwerker | F7: 0.3 | I7: 0.19
K8: Individueller Auf-/Abschlag | L8: 0 | M8: Meine Reno Kosten = | O8: =O6*(1+L8) | P8: =IF(OR(F5=0,F5=""),"",O8/F5) | R8: =SUM(R12:R105)
R10: ↑
B11: Gewerk | C11: Pos. | D11: Gewerk | E11: lfd. Nr. | F11: Maßnahmen | G11: Anteil Lohn- kosten in % | H11: Anteil Material in % | I11: Menge | J11: Einheit | K11: pschl. EP netto | L11: Zeit in h | M11: Zeit in Tagen | N11: Lohnkosten | O11: Materialkosten | P11: Gesamtkosten (Netto) | Q11: Summe pro Gewerk (Netto) | R11: Eingeholte Angebote von Handwerkern
B12: Entmietung | C12: =IF(I12>0,1,"") | D12: =B12 | E12: 1 | F12: Entmietung (Anwaltskosten, Umzugskosten etc.) | J12: Stk | K12: 4000 | L12: 0 | M12: 0 | N12: 0 | O12: 0 | P12: =I12*K12 | Q12: =P12
B13: Entrümpelung Entsorgung | C13: =IF(I13>0,MAX($C$12:C12)+1,"") | D13: =IF(ISBLANK(B13),D12,B13) | E13: 2 | F13: Entrümplung (ohne Entsorgungskosten) | G13: 0.8 | H13: 0.2 | J13: m² | K13: 40 | L13: =(N13/$I$5)/(1+$F$7) | M13: =L13/8 | N13: =P13*G13 | O13: =P13*H13 | P13: =I13*K13 | Q13: =SUM(P13:P14)
C14: =IF(I14>0,MAX($C$12:C13)+1,"") | D14: =IF(ISBLANK(B14),D13,B14) | E14: 3 | F14: Entkernung (Wohn- und Nutzfläche) | G14: 0.9 | H14: 0.1 | J14: m² Wfl. | K14: 55 | L14: =(N14/$I$5)/(1+$F$7) | M14: =L14/8 | N14: =P14*G14 | O14: =P14*H14 | P14: =I14*K14
B15: Fassade | C15: =IF(I15>0,MAX($C$12:C14)+1,"") | D15: =IF(ISBLANK(B15),D14,B15) | E15: 4 | F15: Gerüstkosten Auf-/Abbau (Einrüstung der Fassade) | G15: 0.9 | H15: 0.1 | J15: m² | K15: 8 | L15: =(N15/$I$5)/(1+$F$7) | M15: =L15/8 | N15: =P15*G15 | O15: =P15*H15 | P15: =I15*K15 | Q15: =SUM(P15:P22)
C16: =IF(I16>0,MAX($C$12:C15)+1,"") | D16: =IF(ISBLANK(B16),D15,B16) | E16: 5 | F16: Fassade reinigen | J16: m² | K16: 2.5 | L16: =(N16/$I$5)/(1+$F$7) | M16: =L16/8 | N16: =P16*G16 | O16: =P16*H16 | P16: =I16*K16
C17: =IF(I17>0,MAX($C$12:C16)+1,"") | D17: =IF(ISBLANK(B17),D16,B17) | E17: 6 | F17: Sockel Fassade aufarbeiten | J17: m² | K17: 15 | L17: =(N17/$I$5)/(1+$F$7) | M17: =L17/8 | N17: =P17*G17 | O17: =P17*H17 | P17: =I17*K17
C18: =IF(I18>0,MAX($C$12:C17)+1,"") | D18: =IF(ISBLANK(B18),D17,B18) | E18: 7 | F18: Dämmung WDVS (16mm) | J18: m² | K18: 45 | L18: =(N18/$I$5)/(1+$F$7) | M18: =L18/8 | N18: =P18*G18 | O18: =P18*H18 | P18: =I18*K18
C19: =IF(I19>0,MAX($C$12:C18)+1,"") | D19: =IF(ISBLANK(B19),D18,B19) | E19: 8 | F19: Gewebespachtel | J19: m² | K19: 20 | L19: =(N19/$I$5)/(1+$F$7) | M19: =L19/8 | N19: =P19*G19 | O19: =P19*H19 | P19: =I19*K19
C20: =IF(I20>0,MAX($C$12:C19)+1,"") | D20: =IF(ISBLANK(B20),D19,B20) | E20: 9 | F20: Fassade verputzen | G20: 0.7 | H20: 0.3 | J20: m² | K20: 20 | L20: =(N20/$I$5)/(1+$F$7) | M20: =L20/8 | N20: =P20*G20 | O20: =P20*H20 | P20: =I20*K20
C21: =IF(I21>0,MAX($C$12:C20)+1,"") | D21: =IF(ISBLANK(B21),D20,B21) | E21: 10 | F21: Fenster ausspitzen | J21: Stk | K21: 25 | L21: =(N21/$I$5)/(1+$F$7) | M21: =L21/8 | N21: =P21*G21 | O21: =P21*H21 | P21: =I21*K21
C22: =IF(I22>0,MAX($C$12:C21)+1,"") | D22: =IF(ISBLANK(B22),D20,B22) | E22: 11 | F22: Fassade neu streichen (zweifach) | G22: 0.75 | H22: 0.25 | J22: m² | K22: 12.5 | L22: =(N22/$I$5)/(1+$F$7) | M22: =L22/8 | N22: =P22*G22 | O22: =P22*H22 | P22: =I22*K22
B23: Dach | C23: =IF(I23>0,MAX($C$12:C22)+1,"") | D23: =IF(ISBLANK(B23),D22,B23) | E23: 12 | F23: Dachreinigung | G23: 0.8 | H23: 0.2 | J23: m² | K23: 5 | L23: =(N23/$I$5)/(1+$F$7) | M23: =L23/8 | N23: =P23*G23 | O23: =P23*H23 | P23: =I23*K23 | Q23: =SUM(P23:P27)
C24: =IF(I24>0,MAX($C$12:C23)+1,"") | D24: =IF(ISBLANK(B24),D22,B24) | E24: 13 | F24: Dachbeschichtung / Versiegelung (zweifach) | J24: m² | K24: 25 | L24: =(N24/$I$5)/(1+$F$7) | M24: =L24/8 | N24: =P24*G24 | O24: =P24*H24 | P24: =I24*K24
C25: =IF(I25>0,MAX($C$12:C24)+1,"") | D25: =IF(ISBLANK(B25),D23,B25) | E25: 14 | F25: Dach neu decken | G25: 0.8 | H25: 0.2 | J25: m² | K25: 95 | L25: =(N25/$I$5)/(1+$F$7) | M25: =L25/8 | N25: =P25*G25 | O25: =P25*H25 | P25: =I25*K25
C26: =IF(I26>0,MAX($C$12:C25)+1,"") | D26: =IF(ISBLANK(B26),D25,B26) | E26: 15 | F26: Dachrinne & Fallrohre erneuern | G26: 0.8 | H26: 0.2 | J26: lfd.m | K26: 50 | L26: =(N26/$I$5)/(1+$F$7) | M26: =L26/8 | N26: =P26*G26 | O26: =P26*H26 | P26: =I26*K26
C27: =IF(I27>0,MAX($C$12:C26)+1,"") | D27: =IF(ISBLANK(B27),D26,B27) | E27: 16 | F27: Dachdämmung (inkl. Dampfsperre) | G27: 0.6 | H27: 0.4 | J27: m² | K27: 90 | L27: =(N27/$I$5)/(1+$F$7) | M27: =L27/8 | N27: =P27*G27 | O27: =P27*H27 | P27: =I27*K27
B28: Wände und Decken | C28: =IF(I28>0,MAX($C$12:C27)+1,"") | D28: =IF(ISBLANK(B28),D27,B28) | E28: 17 | F28: Wände und Decken neu tapezieren und streichen | G28: 0.8 | H28: 0.2 | J28: m² Wfl. | K28: =18 | L28: =(N28/$I$5)/(1+$F$7) | M28: =L28/8 | N28: =P28*G28 | O28: =P28*H28 | P28: =I28*K28 | Q28: =SUM(P28:P33)
C29: =IF(I29>0,MAX($C$12:C28)+1,"") | D29: =IF(ISBLANK(B29),D28,B29) | E29: 18 | F29: Wände verputzen | G29: 0.7 | H29: 0.3 | J29: m² Wfl. | K29: 17 | L29: =(N29/$I$5)/(1+$F$7) | M29: =L29/8 | N29: =P29*G29 | O29: =P29*H29 | P29: =I29*K29
C30: =IF(I30>0,MAX($C$12:C29)+1,"") | D30: =IF(ISBLANK(B30),D29,B30) | E30: 19 | F30: Wand einziehen (Trockenbau) | G30: 0.7 | H30: 0.3 | J30: m² | K30: 60 | L30: =(N30/$I$5)/(1+$F$7) | M30: =L30/8 | N30: =P30*G30 | O30: =P30*H30 | P30: =I30*K30
C31: =IF(I31>0,MAX($C$12:C30)+1,"") | D31: =IF(ISBLANK(B31),D30,B31) | E31: 20 | F31: Decke abhängen (Trockenbau) | G31: 0.7 | H31: 0.3 | J31: m² | K31: 44 | L31: =(N31/$I$5)/(1+$F$7) | M31: =L31/8 | N31: =P31*G31 | O31: =P31*H31 | P31: =I31*K31
C32: =IF(I32>0,MAX($C$12:C31)+1,"") | D32: =IF(ISBLANK(B32),D31,B32) | E32: 21 | F32: Tapete entfernen | G32: 0.95 | H32: 0.05 | J32: m² Wfl. | K32: 7 | L32: =(N32/$I$5)/(1+$F$7) | M32: =L32/8 | N32: =P32*G32 | O32: =P32*H32 | P32: =I32*K32
C33: =IF(I33>0,MAX($C$12:C32)+1,"") | D33: =IF(ISBLANK(B33),D32,B33) | E33: 22 | F33: Wände und Decken streichen | G33: 0.8 | H33: 0.2 | J33: m² Wfl. | K33: 8.95 | L33: =(N33/$I$5)/(1+$F$7) | M33: =L33/8 | N33: =P33*G33 | O33: =P33*H33 | P33: =I33*K33
B34: Fussböden | C34: =IF(I34>0,MAX($C$12:C33)+1,"") | D34: =IF(ISBLANK(B34),D33,B34) | E34: 23 | F34: Alten Bodenbelag entfernen | G34: 0.9 | H34: 0.1 | J34: m² | K34: 5.2 | L34: =(N34/$I$5)/(1+$F$7) | M34: =L34/8 | N34: =P34*G34 | O34: =P34*H34 | P34: =I34*K34 | Q34: =SUM(P34:P39)
C35: =IF(I35>0,MAX($C$12:C34)+1,"") | D35: =IF(ISBLANK(B35),D34,B35) | E35: 24 | F35: Balkonfußboden beschichten | G35: 0.8 | H35: 0.2 | J35: Stk | K35: 350 | L35: =(N35/$I$5)/(1+$F$7) | M35: =L35/8 | N35: =P35*G35 | O35: =P35*H35 | P35: =I35*K35
C36: =IF(I36>0,MAX($C$12:C35)+1,"") | D36: =IF(ISBLANK(B36),D35,B36) | E36: 25 | F36: Sockelleisten erneuern pauschal pro Raum | G36: 0.8 | H36: 0.2 | J36: Raum | K36: 78 | L36: =(N36/$I$5)/(1+$F$7) | M36: =L36/8 | N36: =P36*G36 | O36: =P36*H36 | P36: =I36*K36
C37: =IF(I37>0,MAX($C$12:C36)+1,"") | D37: =IF(ISBLANK(B37),D36,B37) | E37: 26 | F37: Laminat / Vinyl verlegen | G37: 0.6 | H37: 0.4 | J37: m² Wfl. | K37: 38 | L37: =(N37/$I$5)/(1+$F$7) | M37: =L37/8 | N37: =P37*G37 | O37: =P37*H37 | P37: =I37*K37
C38: =IF(I38>0,MAX($C$12:C37)+1,"") | D38: =IF(ISBLANK(B38),D37,B38) | E38: 27 | F38: Laminat / Vinyl verlegen (mit Trittschalldämmung) | G38: 0.6 | H38: 0.4 | J38: m² Wfl. | K38: 50 | L38: =(N38/$I$5)/(1+$F$7) | M38: =L38/8 | N38: =P38*G38 | O38: =P38*H38 | P38: =I38*K38
C39: =IF(I39>0,MAX($C$12:C38)+1,"") | D39: =IF(ISBLANK(B39),D38,B39) | E39: 28 | F39: Parkett schleifen und lackieren | G39: 0.7 | H39: 0.3 | J39: m² Wfl. | K39: 80 | L39: =(N39/$I$5)/(1+$F$7) | M39: =L39/8 | N39: =P39*G39 | O39: =P39*H39 | P39: =I39*K39
B40: Fenster und Türen | C40: =IF(I40>0,MAX($C$12:C39)+1,"") | D40: =IF(ISBLANK(B40),D39,B40) | E40: 29 | F40: Geländer entrosten und streichen | G40: 0.85 | H40: 0.15 | J40: lfd.m | K40: 45 | L40: =(N40/$I$5)/(1+$F$7) | M40: =L40/8 | N40: =P40*G40 | O40: =P40*H40 | P40: =I40*K40 | Q40: =SUM(P40:P54)
C41: =IF(I41>0,MAX($C$12:C40)+1,"") | D41: =IF(ISBLANK(B41),D40,B41) | E41: 30 | F41: Holzfenster lackieren | G41: 0.8 | H41: 0.2 | J41: Stk | K41: 120 | L41: =(N41/$I$5)/(1+$F$7) | M41: =L41/8 | N41: =P41*G41 | O41: =P41*H41 | P41: =I41*K41
C42: =IF(I42>0,MAX($C$12:C41)+1,"") | D42: =IF(ISBLANK(B42),D41,B42) | E42: 31 | F42: Tür und Zarge lackieren | G42: 0.7 | H42: 0.3 | J42: Stk | K42: 180 | L42: =(N42/$I$5)/(1+$F$7) | M42: =L42/8 | N42: =P42*G42 | O42: =P42*H42 | P42: =I42*K42
C43: =IF(I43>0,MAX($C$12:C42)+1,"") | D43: =IF(ISBLANK(B43),D42,B43) | E43: 32 | F43: Zarge lackieren | G43: 0.7 | H43: 0.3 | J43: Stk | K43: 80 | L43: =(N43/$I$5)/(1+$F$7) | M43: =L43/8 | N43: =P43*G43 | O43: =P43*H43 | P43: =I43*K43
...

Sheet MIETER
A1: MIETAUFSTELLUNG
R3: § 559 BGB (Modernisierung)
N4: =TODAY() | R4: Modernisierungskosten =
N5: § 558 BGB (Mietspiegel) | R5: Davon 8% umlegbar auf JNKM = | T5: =T4*8%
L6: Mietspiegel → | M6: 10 | N6: Kappungsgrenze = | P6: 0.2 | R6: Erhöhung pro Monat pro qm WFL = | T6: =T5/12/F28 | U6: Tagesaktuelle Mietsituation während dem Projekt | Y6: Modul 4 Output
A7: Haus Nr. | B7: WHG Nr | C7: Etage | D7: Lage | E7: Zimmer | F7: Wohnfläche | G7: Name Mieter | H7: Beginn Miete | I7: letz. Erhöhung | J7: Kaltmiete IST | K7: Garagen-/Stellpl.- miete | L7: IST KM/qm | M7: Δ zu Mietspiegel | N7: Kaltmiete NEU | O7: Stellplätze | P7: NEU KM/qm | Q7: Δ zu Mietspiegel | R7: Kaltmiete SOLL | S7: Stellplätze | T7: SOLL KM/qm | U7: Kaltmiete | V7: Stellplätze | W7: IST KM/qm | X7: Notiz | Y7: Mietspiegel-Obergrenze EUR/m² (per WE)
K8: =IF(AND(NOT(ISNUMBER('Verkauf Cashflow'!AL3)),NOT(ISNUMBER('Verkauf Cashflow'!AM3))),"",N('Verkauf Cashflow'!AL3)+N('Verkauf Cashflow'!AM3)) | L8: =IFERROR(J8/F8,"") | M8: =IF(L8="", "", L8-$M$6) | N8: =IFERROR(IF(J8/F8>(Y8+$M$6)/2,J8,IF(I8<EDATE($N$4,-36),IF(J8*(1+$P$6)/F8<=(Y8+$M$6)/2,J8*(1+$P$6),F8*(Y8+$M$6)/2),J8)),"") | P8: =IFERROR(N8/F8,"") | Q8: =IF(P8="", "", P8-$M$6) | R8: =IF(Y8="","",IFERROR(MAX(J8,(Y8+$T$6)*F8),"")) | T8: =IFERROR(R8/F8,"") | W8: =IFERROR(U8/F8,"")
K9: =IF(AND(NOT(ISNUMBER('Verkauf Cashflow'!AL4)),NOT(ISNUMBER('Verkauf Cashflow'!AM4))),"",N('Verkauf Cashflow'!AL4)+N('Verkauf Cashflow'!AM4)) | L9: =IFERROR(J9/F9,"") | M9: =IF(L9="", "", L9-$M$6) | N9: =IFERROR(IF(J9/F9>(Y9+$M$6)/2,J9,IF(I9<EDATE($N$4,-36),IF(J9*(1+$P$6)/F9<=(Y9+$M$6)/2,J9*(1+$P$6),F9*(Y9+$M$6)/2),J9)),"") | P9: =IFERROR(N9/F9,"") | Q9: =IF(P9="", "", P9-$M$6) | R9: =IF(Y9="","",IFERROR(MAX(J9,(Y9+$T$6)*F9),"")) | T9: =IFERROR(R9/F9,"") | W9: =IFERROR(U9/F9,"")
K10: =IF(AND(NOT(ISNUMBER('Verkauf Cashflow'!AL5)),NOT(ISNUMBER('Verkauf Cashflow'!AM5))),"",N('Verkauf Cashflow'!AL5)+N('Verkauf Cashflow'!AM5)) | L10: =IFERROR(J10/F10,"") | M10: =IF(L10="", "", L10-$M$6) | N10: =IFERROR(IF(J10/F10>(Y10+$M$6)/2,J10,IF(I10<EDATE($N$4,-36),IF(J10*(1+$P$6)/F10<=(Y10+$M$6)/2,J10*(1+$P$6),F10*(Y10+$M$6)/2),J10)),"") | P10: =IFERROR(N10/F10,"") | Q10: =IF(P10="", "", P10-$M$6) | R10: =IF(Y10="","",IFERROR(MAX(J10,(Y10+$T$6)*F10),"")) | T10: =IFERROR(R10/F10,"") | W10: =IFERROR(U10/F10,"")
K11: =IF(AND(NOT(ISNUMBER('Verkauf Cashflow'!AL6)),NOT(ISNUMBER('Verkauf Cashflow'!AM6))),"",N('Verkauf Cashflow'!AL6)+N('Verkauf Cashflow'!AM6)) | L11: =IFERROR(J11/F11,"") | M11: =IF(L11="", "", L11-$M$6) | N11: =IFERROR(IF(J11/F11>(Y11+$M$6)/2,J11,IF(I11<EDATE($N$4,-36),IF(J11*(1+$P$6)/F11<=(Y11+$M$6)/2,J11*(1+$P$6),F11*(Y11+$M$6)/2),J11)),"") | P11: =IFERROR(N11/F11,"") | Q11: =IF(P11="", "", P11-$M$6) | R11: =IF(Y11="","",IFERROR(MAX(J11,(Y11+$T$6)*F11),"")) | T11: =IFERROR(R11/F11,"") | W11: =IFERROR(U11/F11,"")
K12: =IF(AND(NOT(ISNUMBER('Verkauf Cashflow'!AL7)),NOT(ISNUMBER('Verkauf Cashflow'!AM7))),"",N('Verkauf Cashflow'!AL7)+N('Verkauf Cashflow'!AM7)) | L12: =IFERROR(J12/F12,"") | M12: =IF(L12="", "", L12-$M$6) | N12: =IFERROR(IF(J12/F12>(Y12+$M$6)/2,J12,IF(I12<EDATE($N$4,-36),IF(J12*(1+$P$6)/F12<=(Y12+$M$6)/2,J12*(1+$P$6),F12*(Y12+$M$6)/2),J12)),"") | P12: =IFERROR(N12/F12,"") | Q12: =IF(P12="", "", P12-$M$6) | R12: =IF(Y12="","",IFERROR(MAX(J12,(Y12+$T$6)*F12),"")) | T12: =IFERROR(R12/F12,"") | W12: =IFERROR(U12/F12,"")
K13: =IF(AND(NOT(ISNUMBER('Verkauf Cashflow'!AL8)),NOT(ISNUMBER('Verkauf Cashflow'!AM8))),"",N('Verkauf Cashflow'!AL8)+N('Verkauf Cashflow'!AM8)) | L13: =IFERROR(J13/F13,"") | M13: =IF(L13="", "", L13-$M$6) | N13: =IFERROR(IF(J13/F13>(Y13+$M$6)/2,J13,IF(I13<EDATE($N$4,-36),IF(J13*(1+$P$6)/F13<=(Y13+$M$6)/2,J13*(1+$P$6),F13*(Y13+$M$6)/2),J13)),"") | P13: =IFERROR(N13/F13,"") | Q13: =IF(P13="", "", P13-$M$6) | R13: =IF(Y13="","",IFERROR(MAX(J13,(Y13+$T$6)*F13),"")) | T13: =IFERROR(R13/F13,"") | W13: =IFERROR(U13/F13,"")
K14: =IF(AND(NOT(ISNUMBER('Verkauf Cashflow'!AL9)),NOT(ISNUMBER('Verkauf Cashflow'!AM9))),"",N('Verkauf Cashflow'!AL9)+N('Verkauf Cashflow'!AM9)) | L14: =IFERROR(J14/F14,"") | M14: =IF(L14="", "", L14-$M$6) | N14: =IFERROR(IF(J14/F14>(Y14+$M$6)/2,J14,IF(I14<EDATE($N$4,-36),IF(J14*(1+$P$6)/F14<=(Y14+$M$6)/2,J14*(1+$P$6),F14*(Y14+$M$6)/2),J14)),"") | P14: =IFERROR(N14/F14,"") | Q14: =IF(P14="", "", P14-$M$6) | R14: =IF(Y14="","",IFERROR(MAX(J14,(Y14+$T$6)*F14),"")) | T14: =IFERROR(R14/F14,"") | W14: =IFERROR(U14/F14,"")
K15: =IF(AND(NOT(ISNUMBER('Verkauf Cashflow'!AL10)),NOT(ISNUMBER('Verkauf Cashflow'!AM10))),"",N('Verkauf Cashflow'!AL10)+N('Verkauf Cashflow'!AM10)) | L15: =IFERROR(J15/F15,"") | M15: =IF(L15="", "", L15-$M$6) | N15: =IFERROR(IF(J15/F15>(Y15+$M$6)/2,J15,IF(I15<EDATE($N$4,-36),IF(J15*(1+$P$6)/F15<=(Y15+$M$6)/2,J15*(1+$P$6),F15*(Y15+$M$6)/2),J15)),"") | P15: =IFERROR(N15/F15,"") | Q15: =IF(P15="", "", P15-$M$6) | R15: =IF(Y15="","",IFERROR(MAX(J15,(Y15+$T$6)*F15),"")) | T15: =IFERROR(R15/F15,"") | W15: =IFERROR(U15/F15,"")
K16: =IF(AND(NOT(ISNUMBER('Verkauf Cashflow'!AL11)),NOT(ISNUMBER('Verkauf Cashflow'!AM11))),"",N('Verkauf Cashflow'!AL11)+N('Verkauf Cashflow'!AM11)) | L16: =IFERROR(J16/F16,"") | M16: =IF(L16="", "", L16-$M$6) | N16: =IFERROR(IF(J16/F16>(Y16+$M$6)/2,J16,IF(I16<EDATE($N$4,-36),IF(J16*(1+$P$6)/F16<=(Y16+$M$6)/2,J16*(1+$P$6),F16*(Y16+$M$6)/2),J16)),"") | P16: =IFERROR(N16/F16,"") | Q16: =IF(P16="", "", P16-$M$6) | R16: =IF(Y16="","",IFERROR(MAX(J16,(Y16+$T$6)*F16),"")) | T16: =IFERROR(R16/F16,"") | W16: =IFERROR(U16/F16,"")
K17: =IF(AND(NOT(ISNUMBER('Verkauf Cashflow'!AL12)),NOT(ISNUMBER('Verkauf Cashflow'!AM12))),"",N('Verkauf Cashflow'!AL12)+N('Verkauf Cashflow'!AM12)) | L17: =IFERROR(J17/F17,"") | M17: =IF(L17="", "", L17-$M$6) | N17: =IFERROR(IF(J17/F17>(Y17+$M$6)/2,J17,IF(I17<EDATE($N$4,-36),IF(J17*(1+$P$6)/F17<=(Y17+$M$6)/2,J17*(1+$P$6),F17*(Y17+$M$6)/2),J17)),"") | P17: =IFERROR(N17/F17,"") | Q17: =IF(P17="", "", P17-$M$6) | R17: =IF(Y17="","",IFERROR(MAX(J17,(Y17+$T$6)*F17),"")) | T17: =IFERROR(R17/F17,"") | W17: =IFERROR(U17/F17,"")
K18: =IF(AND(NOT(ISNUMBER('Verkauf Cashflow'!AL13)),NOT(ISNUMBER('Verkauf Cashflow'!AM13))),"",N('Verkauf Cashflow'!AL13)+N('Verkauf Cashflow'!AM13)) | L18: =IFERROR(J18/F18,"") | M18: =IF(L18="", "", L18-$M$6) | N18: =IFERROR(IF(J18/F18>(Y18+$M$6)/2,J18,IF(I18<EDATE($N$4,-36),IF(J18*(1+$P$6)/F18<=(Y18+$M$6)/2,J18*(1+$P$6),F18*(Y18+$M$6)/2),J18)),"") | P18: =IFERROR(N18/F18,"") | Q18: =IF(P18="", "", P18-$M$6) | R18: =IF(Y18="","",IFERROR(MAX(J18,(Y18+$T$6)*F18),"")) | T18: =IFERROR(R18/F18,"") | W18: =IFERROR(U18/F18,"")
K19: =IF(AND(NOT(ISNUMBER('Verkauf Cashflow'!AL14)),NOT(ISNUMBER('Verkauf Cashflow'!AM14))),"",N('Verkauf Cashflow'!AL14)+N('Verkauf Cashflow'!AM14)) | L19: =IFERROR(J19/F19,"") | M19: =IF(L19="", "", L19-$M$6) | N19: =IFERROR(IF(J19/F19>(Y19+$M$6)/2,J19,IF(I19<EDATE($N$4,-36),IF(J19*(1+$P$6)/F19<=(Y19+$M$6)/2,J19*(1+$P$6),F19*(Y19+$M$6)/2),J19)),"") | P19: =IFERROR(N19/F19,"") | Q19: =IF(P19="", "", P19-$M$6) | R19: =IF(Y19="","",IFERROR(MAX(J19,(Y19+$T$6)*F19),"")) | T19: =IFERROR(R19/F19,"") | W19: =IFERROR(U19/F19,"")
... K27: =IF(AND(NOT(ISNUMBER('Verkauf Cashflow'!AL22)),NOT(ISNUMBER('Verkauf Cashflow'!AM22))),"",N('Verkauf Cashflow'!AL22)+N('Verkauf Cashflow'!AM22)) | L27: =IFERROR(J27/F27,"") | M27: =IF(L27="", "", L27-$M$6) | N27: =IFERROR(IF(J27/F27>(Y27+$M$6)/2,J27,IF(I27<EDATE($N$4,-36),IF(J27*(1+$P$6)/F27<=(Y27+$M$6)/2,J27*(1+$P$6),F27*(Y27+$M$6)/2),J27)),"") | P27: =IFERROR(N27/F27,"") | Q27: =IF(P27="", "", P27-$M$6) | R27: =IF(Y27="","",IFERROR(MAX(J27,(Y27+$T$6)*F27),"")) | T27: =IFERROR(R27/F27,"") | W27: =IFERROR(U27/F27,"")
F28: =SUM(F8:F27) | J28: =SUM(J8:J27) | K28: =SUM(K8:K27) | L28: =AVERAGE(L8:L27) | N28: =SUM(N8:N27) | O28: =SUM(O8:O27) | P28: =AVERAGE(P8:P27) | R28: =SUM(R8:R27) | S28: =SUM(S8:S27) | T28: =AVERAGE(T8:T27) | U28: =SUM(U8:U27) | V28: =SUM(V8:V27) | W28: =IFERROR(AVERAGE(W8:W27),"")
J29: ↓ | K29: ↓ | N29: ↓ | O29: ↓ | R29: ↓ | S29: ↓
I30: pro Jahr = | J30: =J28*12 | K30: =K28*12 | N30: =N28*12 | O30: =O28*12 | R30: =R28*12 | S30: =S28*12
I31: JNKM = | J31: =J30+K30 | N31: =N30+O30 | R31: =R30+S30
J32: Rendite Einkauf (KP+NK) | K32: =J31/(KALKU!P37+KALKU!J30) | N32: Rendite Einkauf (KP+NK) | O32: =N31/(KALKU!P37+KALKU!J30) | R32: Rendite Einkauf (GIK) | S32: =R31/KALKU!J39

Sheet VERKAUFSMATRIX
A1: VERKAUFSMATRIX
A5: HAUS NR. | B5: WHG NR. | C5: ETAGE | D5: LAGE | E5: ZIMMER | F5: WOHN- FLÄCHE | G5: €/qm PORTALPREISE | H5: €/qm AUF/ABSCHLAG | I5: MIETSITUATION (- 10%) | J5: Auf-/Abschlag Mietsituation | K5: Δ zu Mietspiegel | L5: =MIETER!M6 | M5: BALKON (- 5%) | N5: Auf-/Abschlag Balkon | O5: Baujahr Etagenheizung | P5: Auf-/Abschlag Etagenheizung | Q5: ZUSTAND RENOVIERUNG IM VERKAUF (+5%/- 5%) | R5: Auf-/Abschlag Renovierung | S5: ETAGE / LAGE (- 5%) | T5: ETAGE / LAGE (- 5%) | U5: VERKAUFSPREIS WOHNUNG | V5: PREIS GARAGE / STELLPLATZ | W5: VORSCHLAG VERKAUFSPREIS | X5: INDIVIDUELLER AUF-/ABSCHLAG | Y5: MEIN VERKAUFSPREIS | Z5: VK / qm | AA5: % RENDITE MEIN PREIS
A6: =IF(ISNUMBER(MIETER!F8),IFERROR(MIETER!A8,""),"") | B6: =IF(ISNUMBER(MIETER!F8),IFERROR(MIETER!B8,""),"") | C6: =IF(ISNUMBER(MIETER!F8),IFERROR(MIETER!C8,""),"") | D6: =IF(ISNUMBER(MIETER!F8),IFERROR(MIETER!D8,""),"") | E6: =IF(ISNUMBER(MIETER!F8),IFERROR(MIETER!E8,""),"") | F6: =IF(ISNUMBER(MIETER!F8),IFERROR(MIETER!F8,""),"") | G6: =IF(ISNUMBER(MIETER!F8),KALKU!$I$18,"") | H6: =IF(ISNUMBER(MIETER!F8),KALKU!$N$18,"") | J6: =IF(ISNUMBER(MIETER!F8),IF(I6="vermietet",H6*(-0.1),H6*0),"") | K6: =IF(ISNUMBER(MIETER!F8),IFERROR(MIETER!Q8/MIETER!$M$6,""),"") | L6: =IF(ISNUMBER(MIETER!F8),IF(K6 >= 0%,H6*(0.01), IF(K6 >= -5%,H6*(-0.01), IF(K6 >= -10%,H6*(-0.02), IF(K6 >= -15%,H6*(-0.03), IF(K6 >= -20%,H6*(-0.04), IF(K6 >= -25%,H6*(-0.05), IF(K6 >= -30%,H6*(-0.06), IF(K6 >= -35%,H6*(-0.07), IF(K6 >= -40%,H6*(-0.08), IF(K6 >= -45%,H6*(-0.09), IF(K6 >= -50%, H6*(-0.1), H6*0 ) )))))))))),"") | N6: =IF(NOT(ISNUMBER(H6)),"",IF(M6="Kein Balkon",H6*(-0.05),H6*0)) | P6: =IF(NOT(ISNUMBER(H6)),"",IF(ISBLANK(O6),0,H6*MIN((YEAR(TODAY())-O6)*0.003,0.09)*-1)) | R6: =IF(ISNUMBER(MIETER!F8),IF(Q6="renoviert",H6*0.05,IF(Q6="teilweise renoviert",H6*0,IF(Q6="unrenoviert",H6*-0.05,0))),"") | S6: =IF(ISNUMBER(MIETER!F8),C6,"") | T6: =IF(ISNUMBER(MIETER!F8),IF(OR(S6="EG",S6="1.OG",S6="2.OG",S6="OG",S6="über 2.OG mit Aufzug"),H6*0,IF(OR(S6="UG",S6="über 2.OG ohne Aufzug"),H6*(-0.05),0)),"") | U6: =IF(ISNUMBER(MIETER!F8),IFERROR(F6*(H6+J6+L6+N6+P6+R6+T6),""),"") | V6: =IF(NOT(ISNUMBER(MIETER!F8)),"",N('Verkauf Cashflow'!Q3)+N('Verkauf Cashflow'!R3)) | W6: =IF(ISNUMBER(MIETER!F8),U6+V6,"") | X6: =IF(ISNUMBER('Verkauf Cashflow'!O3),'Verkauf Cashflow'!O3,"") | Y6: =IF(ISNUMBER('Verkauf Cashflow'!S3),'Verkauf Cashflow'!S3,"") | Z6: =IF(ISNUMBER(MIETER!F8),IFERROR(Y6/F6,""),"") | AA6: =IF(ISNUMBER('Verkauf Cashflow'!CF3),'Verkauf Cashflow'!CF3,"")
A7: =IF(ISNUMBER(MIETER!F9),IFERROR(MIETER!A9,""),"") | B7: =IF(ISNUMBER(MIETER!F9),IFERROR(MIETER!B9,""),"") | C7: =IF(ISNUMBER(MIETER!F9),IFERROR(MIETER!C9,""),"") | D7: =IF(ISNUMBER(MIETER!F9),IFERROR(MIETER!D9,""),"") | E7: =IF(ISNUMBER(MIETER!F9),IFERROR(MIETER!E9,""),"") | F7: =IF(ISNUMBER(MIETER!F9),IFERROR(MIETER!F9,""),"") | G7: =IF(ISNUMBER(MIETER!F9),KALKU!$I$18,"") | H7: =IF(ISNUMBER(MIETER!F9),KALKU!$N$18,"") | J7: =IF(ISNUMBER(MIETER!F9),IF(I7="vermietet",H7*(-0.1),H7*0),"") | K7: =IF(ISNUMBER(MIETER!F9),IFERROR(MIETER!Q9/MIETER!$M$6,""),"") | L7: =IF(ISNUMBER(MIETER!F9),IF(K7 >= 0%,H7*(0.01), IF(K7 >= -5%,H7*(-0.01), IF(K7 >= -10%,H7*(-0.02), IF(K7 >= -15%,H7*(-0.03), IF(K7 >= -20%,H7*(-0.04), IF(K7 >= -25%,H7*(-0.05), IF(K7 >= -30%,H7*(-0.06), IF(K7 >= -35%,H7*(-0.07), IF(K7 >= -40%,H7*(-0.08), IF(K7 >= -45%,H7*(-0.09), IF(K7 >= -50%, H7*(-0.1), H7* 0) )))))))))),"") | N7: =IF(NOT(ISNUMBER(H7)),"",IF(M7="Kein Balkon",H7*(-0.05),H7*0)) | P7: =IF(NOT(ISNUMBER(H7)),"",IF(ISBLANK(O7),0,H7*MIN((YEAR(TODAY())-O7)*0.003,0.09)*-1)) | R7: =IF(ISNUMBER(MIETER!F9),IF(Q7="renoviert",H7*0.05,IF(Q7="teilweise renoviert",H7*0,IF(Q7="unrenoviert",H7*-0.05,0))),"") | S7: =IF(ISNUMBER(MIETER!F9),C7,"") | T7: =IF(ISNUMBER(MIETER!F9),IF(OR(S7="EG",S7="1.OG",S7="2.OG",S7="OG",S7="über 2.OG mit Aufzug"),H7*0,IF(OR(S7="UG",S7="über 2.OG ohne Aufzug"),H7*(-0.05),0)),"") | U7: =IF(ISNUMBER(MIETER!F9),IFERROR(F7*(H7+J7+L7+N7+P7+R7+T7),""),"") | V7: =IF(NOT(ISNUMBER(MIETER!F9)),"",N('Verkauf Cashflow'!Q4)+N('Verkauf Cashflow'!R4)) | W7: =IF(ISNUMBER(MIETER!F9),U7+V7,"") | X7: =IF(ISNUMBER('Verkauf Cashflow'!O4),'Verkauf Cashflow'!O4,"") | Y7: =IF(ISNUMBER('Verkauf Cashflow'!S4),'Verkauf Cashflow'!S4,"") | Z7: =IF(ISNUMBER(MIETER!F9),IFERROR(Y7/F7,""),"") | AA7: =IF(ISNUMBER('Verkauf Cashflow'!CF4),'Verkauf Cashflow'!CF4,"")
A8: =IF(ISNUMBER(MIETER!F10),IFERROR(MIETER!A10,""),"") | B8: =IF(ISNUMBER(MIETER!F10),IFERROR(MIETER!B10,""),"") | C8: =IF(ISNUMBER(MIETER!F10),IFERROR(MIETER!C10,""),"") | D8: =IF(ISNUMBER(MIETER!F10),IFERROR(MIETER!D10,""),"") | E8: =IF(ISNUMBER(MIETER!F10),IFERROR(MIETER!E10,""),"") | F8: =IF(ISNUMBER(MIETER!F10),IFERROR(MIETER!F10,""),"") | G8: =IF(ISNUMBER(MIETER!F10),KALKU!$I$18,"") | H8: =IF(ISNUMBER(MIETER!F10),KALKU!$N$18,"") | J8: =IF(ISNUMBER(MIETER!F10),IF(I8="vermietet",H8*(-0.1),H8*0),"") | K8: =IF(ISNUMBER(MIETER!F10),IFERROR(MIETER!Q10/MIETER!$M$6,""),"") | L8: =IF(ISNUMBER(MIETER!F10),IF(K8 >= 0%,H8*(0.01), IF(K8 >= -5%,H8*(-0.01), IF(K8 >= -10%,H8*(-0.02), IF(K8 >= -15%,H8*(-0.03), IF(K8 >= -20%,H8*(-0.04), IF(K8 >= -25%,H8*(-0.05), IF(K8 >= -30%,H8*(-0.06), IF(K8 >= -35%,H8*(-0.07), IF(K8 >= -40%,H8*(-0.08), IF(K8 >= -45%,H8*(-0.09), IF(K8 >= -50%, H8*(-0.1), H8* 0) )))))))))),"") | N8: =IF(NOT(ISNUMBER(H8)),"",IF(M8="Kein Balkon",H8*(-0.05),H8*0)) | P8: =IF(NOT(ISNUMBER(H8)),"",IF(ISBLANK(O8),0,H8*MIN((YEAR(TODAY())-O8)*0.003,0.09)*-1)) | R8: =IF(ISNUMBER(MIETER!F10),IF(Q8="renoviert",H8*0.05,IF(Q8="teilweise renoviert",H8*0,IF(Q8="unrenoviert",H8*-0.05,0))),"") | S8: =IF(ISNUMBER(MIETER!F10),C8,"") | T8: =IF(ISNUMBER(MIETER!F10),IF(OR(S8="EG",S8="1.OG",S8="2.OG",S8="OG",S8="über 2.OG mit Aufzug"),H8*0,IF(OR(S8="UG",S8="über 2.OG ohne Aufzug"),H8*(-0.05),0)),"") | U8: =IF(ISNUMBER(MIETER!F10),IFERROR(F8*(H8+J8+L8+N8+P8+R8+T8),""),"") | V8: =IF(NOT(ISNUMBER(MIETER!F10)),"",N('Verkauf Cashflow'!Q5)+N('Verkauf Cashflow'!R5)) | W8: =IF(ISNUMBER(MIETER!F10),U8+V8,"") | X8: =IF(ISNUMBER('Verkauf Cashflow'!O5),'Verkauf Cashflow'!O5,"") | Y8: =IF(ISNUMBER('Verkauf Cashflow'!S5),'Verkauf Cashflow'!S5,"") | Z8: =IF(ISNUMBER(MIETER!F10),IFERROR(Y8/F8,""),"") | AA8: =IF(ISNUMBER('Verkauf Cashflow'!CF5),'Verkauf Cashflow'!CF5,"")
A9: =IF(ISNUMBER(MIETER!F11),IFERROR(MIETER!A11,""),"") | B9: =IF(ISNUMBER(MIETER!F11),IFERROR(MIETER!B11,""),"") | C9: =IF(ISNUMBER(MIETER!F11),IFERROR(MIETER!C11,""),"") | D9: =IF(ISNUMBER(MIETER!F11),IFERROR(MIETER!D11,""),"") | E9: =IF(ISNUMBER(MIETER!F11),IFERROR(MIETER!E11,""),"") | F9: =IF(ISNUMBER(MIETER!F11),IFERROR(MIETER!F11,""),"") | G9: =IF(ISNUMBER(MIETER!F11),KALKU!$I$18,"") | H9: =IF(ISNUMBER(MIETER!F11),KALKU!$N$18,"") | J9: =IF(ISNUMBER(MIETER!F11),IF(I9="vermietet",H9*(-0.1),H9*0),"") | K9: =IF(ISNUMBER(MIETER!F11),IFERROR(MIETER!Q11/MIETER!$M$6,""),"") | L9: =IF(ISNUMBER(MIETER!F11),IF(K9 >= 0%,H9*(0.01), IF(K9 >= -5%,H9*(-0.01), IF(K9 >= -10%,H9*(-0.02), IF(K9 >= -15%,H9*(-0.03), IF(K9 >= -20%,H9*(-0.04), IF(K9 >= -25%,H9*(-0.05), IF(K9 >= -30%,H9*(-0.06), IF(K9 >= -35%,H9*(-0.07), IF(K9 >= -40%,H9*(-0.08), IF(K9 >= -45%,H9*(-0.09), IF(K9 >= -50%, H9*(-0.1), H9* 0) )))))))))),"") | N9: =IF(NOT(ISNUMBER(H9)),"",IF(M9="Kein Balkon",H9*(-0.05),H9*0)) | P9: =IF(NOT(ISNUMBER(H9)),"",IF(ISBLANK(O9),0,H9*MIN((YEAR(TODAY())-O9)*0.003,0.09)*-1)) | R9: =IF(ISNUMBER(MIETER!F11),IF(Q9="renoviert",H9*0.05,IF(Q9="teilweise renoviert",H9*0,IF(Q9="unrenoviert",H9*-0.05,0))),"") | S9: =IF(ISNUMBER(MIETER!F11),C9,"") | T9: =IF(ISNUMBER(MIETER!F11),IF(OR(S9="EG",S9="1.OG",S9="2.OG",S9="OG",S9="über 2.OG mit Aufzug"),H9*0,IF(OR(S9="UG",S9="über 2.OG ohne Aufzug"),H9*(-0.05),0)),"") | U9: =IF(ISNUMBER(MIETER!F11),IFERROR(F9*(H9+J9+L9+N9+P9+R9+T9),""),"") | V9: =IF(NOT(ISNUMBER(MIETER!F11)),"",N('Verkauf Cashflow'!Q6)+N('Verkauf Cashflow'!R6)) | W9: =IF(ISNUMBER(MIETER!F11),U9+V9,"") | X9: =IF(ISNUMBER('Verkauf Cashflow'!O6),'Verkauf Cashflow'!O6,"") | Y9: =IF(ISNUMBER('Verkauf Cashflow'!S6),'Verkauf Cashflow'!S6,"") | Z9: =IF(ISNUMBER(MIETER!F11),IFERROR(Y9/F9,""),"") | AA9: =IF(ISNUMBER('Verkauf Cashflow'!CF6),'Verkauf Cashflow'!CF6,"")
A10: =IF(ISNUMBER(MIETER!F12),IFERROR(MIETER!A12,""),"") | B10: =IF(ISNUMBER(MIETER!F12),IFERROR(MIETER!B12,""),"") | C10: =IF(ISNUMBER(MIETER!F12),IFERROR(MIETER!C12,""),"") | D10: =IF(ISNUMBER(MIETER!F12),IFERROR(MIETER!D12,""),"") | E10: =IF(ISNUMBER(MIETER!F12),IFERROR(MIETER!E12,""),"") | F10: =IF(ISNUMBER(MIETER!F12),IFERROR(MIETER!F12,""),"") | G10: =IF(ISNUMBER(MIETER!F12),KALKU!$I$18,"") | H10: =IF(ISNUMBER(MIETER!F12),KALKU!$N$18,"") | J10: =IF(ISNUMBER(MIETER!F12),IF(I10="vermietet",H10*(-0.1),H10*0),"") | K10: =IF(ISNUMBER(MIETER!F12),IFERROR(MIETER!Q12/MIETER!$M$6,""),"") | L10: =IF(ISNUMBER(MIETER!F12),IF(K10 >= 0%,H10*(0.01), IF(K10 >= -5%,H10*(-0.01), IF(K10 >= -10%,H10*(-0.02), IF(K10 >= -15%,H10*(-0.03), IF(K10 >= -20%,H10*(-0.04), IF(K10 >= -25%,H10*(-0.05), IF(K10 >= -30%,H10*(-0.06), IF(K10 >= -35%,H10*(-0.07), IF(K10 >= -40%,H10*(-0.08), IF(K10 >= -45%,H10*(-0.09), IF(K10 >= -50%, H10*(-0.1), H10* 0) )))))))))),"") | N10: =IF(NOT(ISNUMBER(H10)),"",IF(M10="Kein Balkon",H10*(-0.05),H10*0)) | P10: =IF(NOT(ISNUMBER(H10)),"",IF(ISBLANK(O10),0,H10*MIN((YEAR(TODAY())-O10)*0.003,0.09)*-1)) | R10: =IF(ISNUMBER(MIETER!F12),IF(Q10="renoviert",H10*0.05,IF(Q10="teilweise renoviert",H10*0,IF(Q10="unrenoviert",H10*-0.05,0))),"") | S10: =IF(ISNUMBER(MIETER!F12),C10,"") | T10: =IF(ISNUMBER(MIETER!F12),IF(OR(S10="EG",S10="1.OG",S10="2.OG",S10="OG",S10="über 2.OG mit Aufzug"),H10*0,IF(OR(S10="UG",S10="über 2.OG ohne Aufzug"),H10*(-0.05),0)),"") | U10: =IF(ISNUMBER(MIETER!F12),IFERROR(F10*(H10+J10+L10+N10+P10+R10+T10),""),"") | V10: =IF(NOT(ISNUMBER(MIETER!F12)),"",N('Verkauf Cashflow'!Q7)+N('Verkauf Cashflow'!R7)) | W10: =IF(ISNUMBER(MIETER!F12),U10+V10,"") | X10: =IF(ISNUMBER('Verkauf Cashflow'!O7),'Verkauf Cashflow'!O7,"") | Y10: =IF(ISNUMBER('Verkauf Cashflow'!S7),'Verkauf Cashflow'!S7,"") | Z10: =IF(ISNUMBER(MIETER!F12),IFERROR(Y10/F10,""),"") | AA10: =IF(ISNUMBER('Verkauf Cashflow'!CF7),'Verkauf Cashflow'!CF7,"")
A11: =IF(ISNUMBER(MIETER!F13),IFERROR(MIETER!A13,""),"") | B11: =IF(ISNUMBER(MIETER!F13),IFERROR(MIETER!B13,""),"") | C11: =IF(ISNUMBER(MIETER!F13),IFERROR(MIETER!C13,""),"") | D11: =IF(ISNUMBER(MIETER!F13),IFERROR(MIETER!D13,""),"") | E11: =IF(ISNUMBER(MIETER!F13),IFERROR(MIETER!E13,""),"") | F11: =IF(ISNUMBER(MIETER!F13),IFERROR(MIETER!F13,""),"") | G11: =IF(ISNUMBER(MIETER!F13),KALKU!$I$18,"") | H11: =IF(ISNUMBER(MIETER!F13),KALKU!$N$18,"") | J11: =IF(ISNUMBER(MIETER!F13),IF(I11="vermietet",H11*(-0.1),H11*0),"") | K11: =IF(ISNUMBER(MIETER!F13),IFERROR(MIETER!Q13/MIETER!$M$6,""),"") | L11: =IF(ISNUMBER(MIETER!F13),IF(K11 >= 0%,H11*(0.01), IF(K11 >= -5%,H11*(-0.01), IF(K11 >= -10%,H11*(-0.02), IF(K11 >= -15%,H11*(-0.03), IF(K11 >= -20%,H11*(-0.04), IF(K11 >= -25%,H11*(-0.05), IF(K11 >= -30%,H11*(-0.06), IF(K11 >= -35%,H11*(-0.07), IF(K11 >= -40%,H11*(-0.08), IF(K11 >= -45%,H11*(-0.09), IF(K11 >= -50%, H11*(-0.1), H11* 0) )))))))))),"") | N11: =IF(NOT(ISNUMBER(H11)),"",IF(M11="Kein Balkon",H11*(-0.05),H11*0)) | P11: =IF(NOT(ISNUMBER(H11)),"",IF(ISBLANK(O11),0,H11*MIN((YEAR(TODAY())-O11)*0.003,0.09)*-1)) | R11: =IF(ISNUMBER(MIETER!F13),IF(Q11="renoviert",H11*0.05,IF(Q11="teilweise renoviert",H11*0,IF(Q11="unrenoviert",H11*-0.05,0))),"") | S11: =IF(ISNUMBER(MIETER!F13),C11,"") | T11: =IF(ISNUMBER(MIETER!F13),IF(OR(S11="EG",S11="1.OG",S11="2.OG",S11="OG",S11="über 2.OG mit Aufzug"),H11*0,IF(OR(S11="UG",S11="über 2.OG ohne Aufzug"),H11*(-0.05),0)),"") | U11: =IF(ISNUMBER(MIETER!F13),IFERROR(F11*(H11+J11+L11+N11+P11+R11+T11),""),"") | V11: =IF(NOT(ISNUMBER(MIETER!F13)),"",N('Verkauf Cashflow'!Q8)+N('Verkauf Cashflow'!R8)) | W11: =IF(ISNUMBER(MIETER!F13),U11+V11,"") | X11: =IF(ISNUMBER('Verkauf Cashflow'!O8),'Verkauf Cashflow'!O8,"") | Y11: =IF(ISNUMBER('Verkauf Cashflow'!S8),'Verkauf Cashflow'!S8,"") | Z11: =IF(ISNUMBER(MIETER!F13),IFERROR(Y11/F11,""),"") | AA11: =IF(ISNUMBER('Verkauf Cashflow'!CF8),'Verkauf Cashflow'!CF8,"")
A12: =IF(ISNUMBER(MIETER!F14),IFERROR(MIETER!A14,""),"") | B12: =IF(ISNUMBER(MIETER!F14),IFERROR(MIETER!B14,""),"") | C12: =IF(ISNUMBER(MIETER!F14),IFERROR(MIETER!C14,""),"") | D12: =IF(ISNUMBER(MIETER!F14),IFERROR(MIETER!D14,""),"") | E12: =IF(ISNUMBER(MIETER!F14),IFERROR(MIETER!E14,""),"") | F12: =IF(ISNUMBER(MIETER!F14),IFERROR(MIETER!F14,""),"") | G12: =IF(ISNUMBER(MIETER!F14),KALKU!$I$18,"") | H12: =IF(ISNUMBER(MIETER!F14),KALKU!$N$18,"") | J12: =IF(ISNUMBER(MIETER!F14),IF(I12="vermietet",H12*(-0.1),H12*0),"") | K12: =IF(ISNUMBER(MIETER!F14),IFERROR(MIETER!Q14/MIETER!$M$6,""),"") | L12: =IF(ISNUMBER(MIETER!F14),IF(K12 >= 0%,H12*(0.01), IF(K12 >= -5%,H12*(-0.01), IF(K12 >= -10%,H12*(-0.02), IF(K12 >= -15%,H12*(-0.03), IF(K12 >= -20%,H12*(-0.04), IF(K12 >= -25%,H12*(-0.05), IF(K12 >= -30%,H12*(-0.06), IF(K12 >= -35%,H12*(-0.07), IF(K12 >= -40%,H12*(-0.08), IF(K12 >= -45%,H12*(-0.09), IF(K12 >= -50%, H12*(-0.1), H12* 0) )))))))))),"") | N12: =IF(NOT(ISNUMBER(H12)),"",IF(M12="Kein Balkon",H12*(-0.05),H12*0)) | P12: =IF(NOT(ISNUMBER(H12)),"",IF(ISBLANK(O12),0,H12*MIN((YEAR(TODAY())-O12)*0.003,0.09)*-1)) | R12: =IF(ISNUMBER(MIETER!F14),IF(Q12="renoviert",H12*0.05,IF(Q12="teilweise renoviert",H12*0,IF(Q12="unrenoviert",H12*-0.05,0))),"") | S12: =IF(ISNUMBER(MIETER!F14),C12,"") | T12: =IF(ISNUMBER(MIETER!F14),IF(OR(S12="EG",S12="1.OG",S12="2.OG",S12="OG",S12="über 2.OG mit Aufzug"),H12*0,IF(OR(S12="UG",S12="über 2.OG ohne Aufzug"),H12*(-0.05),0)),"") | U12: =IF(ISNUMBER(MIETER!F14),IFERROR(F12*(H12+J12+L12+N12+P12+R12+T12),""),"") | V12: =IF(NOT(ISNUMBER(MIETER!F14)),"",N('Verkauf Cashflow'!Q9)+N('Verkauf Cashflow'!R9)) | W12: =IF(ISNUMBER(MIETER!F14),U12+V12,"") | X12: =IF(ISNUMBER('Verkauf Cashflow'!O9),'Verkauf Cashflow'!O9,"") | Y12: =IF(ISNUMBER('Verkauf Cashflow'!S9),'Verkauf Cashflow'!S9,"") | Z12: =IF(ISNUMBER(MIETER!F14),IFERROR(Y12/F12,""),"") | AA12: =IF(ISNUMBER('Verkauf Cashflow'!CF9),'Verkauf Cashflow'!CF9,"")
A13: =IF(ISNUMBER(MIETER!F15),IFERROR(MIETER!A15,""),"") | B13: =IF(ISNUMBER(MIETER!F15),IFERROR(MIETER!B15,""),"") | C13: =IF(ISNUMBER(MIETER!F15),IFERROR(MIETER!C15,""),"") | D13: =IF(ISNUMBER(MIETER!F15),IFERROR(MIETER!D15,""),"") | E13: =IF(ISNUMBER(MIETER!F15),IFERROR(MIETER!E15,""),"") | F13: =IF(ISNUMBER(MIETER!F15),IFERROR(MIETER!F15,""),"") | G13: =IF(ISNUMBER(MIETER!F15),KALKU!$I$18,"") | H13: =IF(ISNUMBER(MIETER!F15),KALKU!$N$18,"") | J13: =IF(ISNUMBER(MIETER!F15),IF(I13="vermietet",H13*(-0.1),H13*0),"") | K13: =IF(ISNUMBER(MIETER!F15),IFERROR(MIETER!Q15/MIETER!$M$6,""),"") | L13: =IF(ISNUMBER(MIETER!F15),IF(K13 >= 0%,H13*(0.01), IF(K13 >= -5%,H13*(-0.01), IF(K13 >= -10%,H13*(-0.02), IF(K13 >= -15%,H13*(-0.03), IF(K13 >= -20%,H13*(-0.04), IF(K13 >= -25%,H13*(-0.05), IF(K13 >= -30%,H13*(-0.06), IF(K13 >= -35%,H13*(-0.07), IF(K13 >= -40%,H13*(-0.08), IF(K13 >= -45%,H13*(-0.09), IF(K13 >= -50%, H13*(-0.1), H13* 0) )))))))))),"") | N13: =IF(NOT(ISNUMBER(H13)),"",IF(M13="Kein Balkon",H13*(-0.05),H13*0)) | P13: =IF(NOT(ISNUMBER(H13)),"",IF(ISBLANK(O13),0,H13*MIN((YEAR(TODAY())-O13)*0.003,0.09)*-1)) | R13: =IF(ISNUMBER(MIETER!F15),IF(Q13="renoviert",H13*0.05,IF(Q13="teilweise renoviert",H13*0,IF(Q13="unrenoviert",H13*-0.05,0))),"") | S13: =IF(ISNUMBER(MIETER!F15),C13,"") | T13: =IF(ISNUMBER(MIETER!F15),IF(OR(S13="EG",S13="1.OG",S13="2.OG",S13="OG",S13="über 2.OG mit Aufzug"),H13*0,IF(OR(S13="UG",S13="über 2.OG ohne Aufzug"),H13*(-0.05),0)),"") | U13: =IF(ISNUMBER(MIETER!F15),IFERROR(F13*(H13+J13+L13+N13+P13+R13+T13),""),"") | V13: =IF(NOT(ISNUMBER(MIETER!F15)),"",N('Verkauf Cashflow'!Q10)+N('Verkauf Cashflow'!R10)) | W13: =IF(ISNUMBER(MIETER!F15),U13+V13,"") | X13: =IF(ISNUMBER('Verkauf Cashflow'!O10),'Verkauf Cashflow'!O10,"") | Y13: =IF(ISNUMBER('Verkauf Cashflow'!S10),'Verkauf Cashflow'!S10,"") | Z13: =IF(ISNUMBER(MIETER!F15),IFERROR(Y13/F13,""),"") | AA13: =IF(ISNUMBER('Verkauf Cashflow'!CF10),'Verkauf Cashflow'!CF10,"")
A14: =IF(ISNUMBER(MIETER!F16),IFERROR(MIETER!A16,""),"") | B14: =IF(ISNUMBER(MIETER!F16),IFERROR(MIETER!B16,""),"") | C14: =IF(ISNUMBER(MIETER!F16),IFERROR(MIETER!C16,""),"") | D14: =IF(ISNUMBER(MIETER!F16),IFERROR(MIETER!D16,""),"") | E14: =IF(ISNUMBER(MIETER!F16),IFERROR(MIETER!E16,""),"") | F14: =IF(ISNUMBER(MIETER!F16),IFERROR(MIETER!F16,""),"") | G14: =IF(ISNUMBER(MIETER!F16),KALKU!$I$18,"") | H14: =IF(ISNUMBER(MIETER!F16),KALKU!$N$18,"") | J14: =IF(ISNUMBER(MIETER!F16),IF(I14="vermietet",H14*(-0.1),H14*0),"") | K14: =IF(ISNUMBER(MIETER!F16),IFERROR(MIETER!Q16/MIETER!$M$6,""),"") | L14: =IF(ISNUMBER(MIETER!F16),IF(K14 >= 0%,H14*(0.01), IF(K14 >= -5%,H14*(-0.01), IF(K14 >= -10%,H14*(-0.02), IF(K14 >= -15%,H14*(-0.03), IF(K14 >= -20%,H14*(-0.04), IF(K14 >= -25%,H14*(-0.05), IF(K14 >= -30%,H14*(-0.06), IF(K14 >= -35%,H14*(-0.07), IF(K14 >= -40%,H14*(-0.08), IF(K14 >= -45%,H14*(-0.09), IF(K14 >= -50%, H14*(-0.1), H14* 0) )))))))))),"") | N14: =IF(NOT(ISNUMBER(H14)),"",IF(M14="Kein Balkon",H14*(-0.05),H14*0)) | P14: =IF(NOT(ISNUMBER(H14)),"",IF(ISBLANK(O14),0,H14*MIN((YEAR(TODAY())-O14)*0.003,0.09)*-1)) | R14: =IF(ISNUMBER(MIETER!F16),IF(Q14="renoviert",H14*0.05,IF(Q14="teilweise renoviert",H14*0,IF(Q14="unrenoviert",H14*-0.05,0))),"") | S14: =IF(ISNUMBER(MIETER!F16),C14,"") | T14: =IF(ISNUMBER(MIETER!F16),IF(OR(S14="EG",S14="1.OG",S14="2.OG",S14="OG",S14="über 2.OG mit Aufzug"),H14*0,IF(OR(S14="UG",S14="über 2.OG ohne Aufzug"),H14*(-0.05),0)),"") | U14: =IF(ISNUMBER(MIETER!F16),IFERROR(F14*(H14+J14+L14+N14+P14+R14+T14),""),"") | V14: =IF(NOT(ISNUMBER(MIETER!F16)),"",N('Verkauf Cashflow'!Q11)+N('Verkauf Cashflow'!R11)) | W14: =IF(ISNUMBER(MIETER!F16),U14+V14,"") | X14: =IF(ISNUMBER('Verkauf Cashflow'!O11),'Verkauf Cashflow'!O11,"") | Y14: =IF(ISNUMBER('Verkauf Cashflow'!S11),'Verkauf Cashflow'!S11,"") | Z14: =IF(ISNUMBER(MIETER!F16),IFERROR(Y14/F14,""),"") | AA14: =IF(ISNUMBER('Verkauf Cashflow'!CF11),'Verkauf Cashflow'!CF11,"")
A15: =IF(ISNUMBER(MIETER!F17),IFERROR(MIETER!A17,""),"") | B15: =IF(ISNUMBER(MIETER!F17),IFERROR(MIETER!B17,""),"") | C15: =IF(ISNUMBER(MIETER!F17),IFERROR(MIETER!C17,""),"") | D15: =IF(ISNUMBER(MIETER!F17),IFERROR(MIETER!D17,""),"") | E15: =IF(ISNUMBER(MIETER!F17),IFERROR(MIETER!E17,""),"") | F15: =IF(ISNUMBER(MIETER!F17),IFERROR(MIETER!F17,""),"") | G15: =IF(ISNUMBER(MIETER!F17),KALKU!$I$18,"") | H15: =IF(ISNUMBER(MIETER!F17),KALKU!$N$18,"") | J15: =IF(ISNUMBER(MIETER!F17),IF(I15="vermietet",H15*(-0.1),H15*0),"") | K15: =IF(ISNUMBER(MIETER!F17),IFERROR(MIETER!Q17/MIETER!$M$6,""),"") | L15: =IF(ISNUMBER(MIETER!F17),IF(K15 >= 0%,H15*(0.01), IF(K15 >= -5%,H15*(-0.01), IF(K15 >= -10%,H15*(-0.02), IF(K15 >= -15%,H15*(-0.03), IF(K15 >= -20%,H15*(-0.04), IF(K15 >= -25%,H15*(-0.05), IF(K15 >= -30%,H15*(-0.06), IF(K15 >= -35%,H15*(-0.07), IF(K15 >= -40%,H15*(-0.08), IF(K15 >= -45%,H15*(-0.09), IF(K15 >= -50%, H15*(-0.1), H15* 0) )))))))))),"") | N15: =IF(NOT(ISNUMBER(H15)),"",IF(M15="Kein Balkon",H15*(-0.05),H15*0)) | P15: =IF(NOT(ISNUMBER(H15)),"",IF(ISBLANK(O15),0,H15*MIN((YEAR(TODAY())-O15)*0.003,0.09)*-1)) | R15: =IF(ISNUMBER(MIETER!F17),IF(Q15="renoviert",H15*0.05,IF(Q15="teilweise renoviert",H15*0,IF(Q15="unrenoviert",H15*-0.05,0))),"") | S15: =IF(ISNUMBER(MIETER!F17),C15,"") | T15: =IF(ISNUMBER(MIETER!F17),IF(OR(S15="EG",S15="1.OG",S15="2.OG",S15="OG",S15="über 2.OG mit Aufzug"),H15*0,IF(OR(S15="UG",S15="über 2.OG ohne Aufzug"),H15*(-0.05),0)),"") | U15: =IF(ISNUMBER(MIETER!F17),IFERROR(F15*(H15+J15+L15+N15+P15+R15+T15),""),"") | V15: =IF(NOT(ISNUMBER(MIETER!F17)),"",N('Verkauf Cashflow'!Q12)+N('Verkauf Cashflow'!R12)) | W15: =IF(ISNUMBER(MIETER!F17),U15+V15,"") | X15: =IF(ISNUMBER('Verkauf Cashflow'!O12),'Verkauf Cashflow'!O12,"") | Y15: =IF(ISNUMBER('Verkauf Cashflow'!S12),'Verkauf Cashflow'!S12,"") | Z15: =IF(ISNUMBER(MIETER!F17),IFERROR(Y15/F15,""),"") | AA15: =IF(ISNUMBER('Verkauf Cashflow'!CF12),'Verkauf Cashflow'!CF12,"")
A16: =IF(ISNUMBER(MIETER!F18),IFERROR(MIETER!A18,""),"") | B16: =IF(ISNUMBER(MIETER!F18),IFERROR(MIETER!B18,""),"") | C16: =IF(ISNUMBER(MIETER!F18),IFERROR(MIETER!C18,""),"") | D16: =IF(ISNUMBER(MIETER!F18),IFERROR(MIETER!D18,""),"") | E16: =IF(ISNUMBER(MIETER!F18),IFERROR(MIETER!E18,""),"") | F16: =IF(ISNUMBER(MIETER!F18),IFERROR(MIETER!F18,""),"") | G16: =IF(ISNUMBER(MIETER!F18),KALKU!$I$18,"") | H16: =IF(ISNUMBER(MIETER!F18),KALKU!$N$18,"") | J16: =IF(ISNUMBER(MIETER!F18),IF(I16="vermietet",H16*(-0.1),H16*0),"") | K16: =IF(ISNUMBER(MIETER!F18),IFERROR(MIETER!Q18/MIETER!$M$6,""),"") | L16: =IF(ISNUMBER(MIETER!F18),IF(K16 >= 0%,H16*(0.01), IF(K16 >= -5%,H16*(-0.01), IF(K16 >= -10%,H16*(-0.02), IF(K16 >= -15%,H16*(-0.03), IF(K16 >= -20%,H16*(-0.04), IF(K16 >= -25%,H16*(-0.05), IF(K16 >= -30%,H16*(-0.06), IF(K16 >= -35%,H16*(-0.07), IF(K16 >= -40%,H16*(-0.08), IF(K16 >= -45%,H16*(-0.09), IF(K16 >= -50%, H16*(-0.1), H16* 0) )))))))))),"") | N16: =IF(NOT(ISNUMBER(H16)),"",IF(M16="Kein Balkon",H16*(-0.05),H16*0)) | P16: =IF(NOT(ISNUMBER(H16)),"",IF(ISBLANK(O16),0,H16*MIN((YEAR(TODAY())-O16)*0.003,0.09)*-1)) | R16: =IF(ISNUMBER(MIETER!F18),IF(Q16="renoviert",H16*0.05,IF(Q16="teilweise renoviert",H16*0,IF(Q16="unrenoviert",H16*-0.05,0))),"") | S16: =IF(ISNUMBER(MIETER!F18),C16,"") | T16: =IF(ISNUMBER(MIETER!F18),IF(OR(S16="EG",S16="1.OG",S16="2.OG",S16="OG",S16="über 2.OG mit Aufzug"),H16*0,IF(OR(S16="UG",S16="über 2.OG ohne Aufzug"),H16*(-0.05),0)),"") | U16: =IF(ISNUMBER(MIETER!F18),IFERROR(F16*(H16+J16+L16+N16+P16+R16+T16),""),"") | V16: =IF(NOT(ISNUMBER(MIETER!F18)),"",N('Verkauf Cashflow'!Q13)+N('Verkauf Cashflow'!R13)) | W16: =IF(ISNUMBER(MIETER!F18),U16+V16,"") | X16: =IF(ISNUMBER('Verkauf Cashflow'!O13),'Verkauf Cashflow'!O13,"") | Y16: =IF(ISNUMBER('Verkauf Cashflow'!S13),'Verkauf Cashflow'!S13,"") | Z16: =IF(ISNUMBER(MIETER!F18),IFERROR(Y16/F16,""),"") | AA16: =IF(ISNUMBER('Verkauf Cashflow'!CF13),'Verkauf Cashflow'!CF13,"")
A17: =IF(ISNUMBER(MIETER!F19),IFERROR(MIETER!A19,""),"") | B17: =IF(ISNUMBER(MIETER!F19),IFERROR(MIETER!B19,""),"") | C17: =IF(ISNUMBER(MIETER!F19),IFERROR(MIETER!C19,""),"") | D17: =IF(ISNUMBER(MIETER!F19),IFERROR(MIETER!D19,""),"") | E17: =IF(ISNUMBER(MIETER!F19),IFERROR(MIETER!E19,""),"") | F17: =IF(ISNUMBER(MIETER!F19),IFERROR(MIETER!F19,""),"") | G17: =IF(ISNUMBER(MIETER!F19),KALKU!$I$18,"") | H17: =IF(ISNUMBER(MIETER!F19),KALKU!$N$18,"") | J17: =IF(ISNUMBER(MIETER!F19),IF(I17="vermietet",H17*(-0.1),H17*0),"") | K17: =IF(ISNUMBER(MIETER!F19),IFERROR(MIETER!Q19/MIETER!$M$6,""),"") | L17: =IF(ISNUMBER(MIETER!F19),IF(K17 >= 0%,H17*(0.01), IF(K17 >= -5%,H17*(-0.01), IF(K17 >= -10%,H17*(-0.02), IF(K17 >= -15%,H17*(-0.03), IF(K17 >= -20%,H17*(-0.04), IF(K17 >= -25%,H17*(-0.05), IF(K17 >= -30%,H17*(-0.06), IF(K17 >= -35%,H17*(-0.07), IF(K17 >= -40%,H17*(-0.08), IF(K17 >= -45%,H17*(-0.09), IF(K17 >= -50%, H17*(-0.1), H17* 0) )))))))))),"") | N17: =IF(NOT(ISNUMBER(H17)),"",IF(M17="Kein Balkon",H17*(-0.05),H17*0)) | P17: =IF(NOT(ISNUMBER(H17)),"",IF(ISBLANK(O17),0,H17*MIN((YEAR(TODAY())-O17)*0.003,0.09)*-1)) | R17: =IF(ISNUMBER(MIETER!F19),IF(Q17="renoviert",H17*0.05,IF(Q17="teilweise renoviert",H17*0,IF(Q17="unrenoviert",H17*-0.05,0))),"") | S17: =IF(ISNUMBER(MIETER!F19),C17,"") | T17: =IF(ISNUMBER(MIETER!F19),IF(OR(S17="EG",S17="1.OG",S17="2.OG",S17="OG",S17="über 2.OG mit Aufzug"),H17*0,IF(OR(S17="UG",S17="über 2.OG ohne Aufzug"),H17*(-0.05),0)),"") | U17: =IF(ISNUMBER(MIETER!F19),IFERROR(F17*(H17+J17+L17+N17+P17+R17+T17),""),"") | V17: =IF(NOT(ISNUMBER(MIETER!F19)),"",N('Verkauf Cashflow'!Q14)+N('Verkauf Cashflow'!R14)) | W17: =IF(ISNUMBER(MIETER!F19),U17+V17,"") | X17: =IF(ISNUMBER('Verkauf Cashflow'!O14),'Verkauf Cashflow'!O14,"") | Y17: =IF(ISNUMBER('Verkauf Cashflow'!S14),'Verkauf Cashflow'!S14,"") | Z17: =IF(ISNUMBER(MIETER!F19),IFERROR(Y17/F17,""),"") | AA17: =IF(ISNUMBER('Verkauf Cashflow'!CF14),'Verkauf Cashflow'!CF14,"")
A18: =IF(ISNUMBER(MIETER!F20),IFERROR(MIETER!A20,""),"") | B18: =IF(ISNUMBER(MIETER!F20),IFERROR(MIETER!B20,""),"") | C18: =IF(ISNUMBER(MIETER!F20),IFERROR(MIETER!C20,""),"") | D18: =IF(ISNUMBER(MIETER!F20),IFERROR(MIETER!D20,""),"") | E18: =IF(ISNUMBER(MIETER!F20),IFERROR(MIETER!E20,""),"") | F18: =IF(ISNUMBER(MIETER!F20),IFERROR(MIETER!F20,""),"") | G18: =IF(ISNUMBER(MIETER!F20),KALKU!$I$18,"") | H18: =IF(ISNUMBER(MIETER!F20),KALKU!$N$18,"") | J18: =IF(ISNUMBER(MIETER!F20),IF(I18="vermietet",H18*(-0.1),H18*0),"") | K18: =IF(ISNUMBER(MIETER!F20),IFERROR(MIETER!Q20/MIETER!$M$6,""),"") | L18: =IF(ISNUMBER(MIETER!F20),IF(K18 >= 0%,H18*(0.01), IF(K18 >= -5%,H18*(-0.01), IF(K18 >= -10%,H18*(-0.02), IF(K18 >= -15%,H18*(-0.03), IF(K18 >= -20%,H18*(-0.04), IF(K18 >= -25%,H18*(-0.05), IF(K18 >= -30%,H18*(-0.06), IF(K18 >= -35%,H18*(-0.07), IF(K18 >= -40%,H18*(-0.08), IF(K18 >= -45%,H18*(-0.09), IF(K18 >= -50%, H18*(-0.1), H18* 0) )))))))))),"") | N18: =IF(NOT(ISNUMBER(H18)),"",IF(M18="Kein Balkon",H18*(-0.05),H18*0)) | P18: =IF(NOT(ISNUMBER(H18)),"",IF(ISBLANK(O18),0,H18*MIN((YEAR(TODAY())-O18)*0.003,0.09)*-1)) | R18: =IF(ISNUMBER(MIETER!F20),IF(Q18="renoviert",H18*0.05,IF(Q18="teilweise renoviert",H18*0,IF(Q18="unrenoviert",H18*-0.05,0))),"") | S18: =IF(ISNUMBER(MIETER!F20),C18,"") | T18: =IF(ISNUMBER(MIETER!F20),IF(OR(S18="EG",S18="1.OG",S18="2.OG",S18="OG",S18="über 2.OG mit Aufzug"),H18*0,IF(OR(S18="UG",S18="über 2.OG ohne Aufzug"),H18*(-0.05),0)),"") | U18: =IF(ISNUMBER(MIETER!F20),IFERROR(F18*(H18+J18+L18+N18+P18+R18+T18),""),"") | V18: =IF(NOT(ISNUMBER(MIETER!F20)),"",N('Verkauf Cashflow'!Q15)+N('Verkauf Cashflow'!R15)) | W18: =IF(ISNUMBER(MIETER!F20),U18+V18,"") | X18: =IF(ISNUMBER('Verkauf Cashflow'!O15),'Verkauf Cashflow'!O15,"") | Y18: =IF(ISNUMBER('Verkauf Cashflow'!S15),'Verkauf Cashflow'!S15,"") | Z18: =IF(ISNUMBER(MIETER!F20),IFERROR(Y18/F18,""),"") | AA18: =IF(ISNUMBER('Verkauf Cashflow'!CF15),'Verkauf Cashflow'!CF15,"")
... A25: =IF(ISNUMBER(MIETER!F27),IFERROR(MIETER!A27,""),"") | B25: =IF(ISNUMBER(MIETER!F27),IFERROR(MIETER!B27,""),"") | C25: =IF(ISNUMBER(MIETER!F27),IFERROR(MIETER!C27,""),"") | D25: =IF(ISNUMBER(MIETER!F27),IFERROR(MIETER!D27,""),"") | E25: =IF(ISNUMBER(MIETER!F27),IFERROR(MIETER!E27,""),"") | F25: =IF(ISNUMBER(MIETER!F27),IFERROR(MIETER!F27,""),"") | G25: =IF(ISNUMBER(MIETER!F27),KALKU!$I$18,"") | H25: =IF(ISNUMBER(MIETER!F27),KALKU!$N$18,"") | J25: =IF(ISNUMBER(MIETER!F27),IF(I25="vermietet",H25*(-0.1),H25*0),"") | K25: =IF(ISNUMBER(MIETER!F27),IFERROR(MIETER!Q27/MIETER!$M$6,""),"") | L25: =IF(ISNUMBER(MIETER!F27),IF(K25 >= 0%,H25*(0.01), IF(K25 >= -5%,H25*(-0.01), IF(K25 >= -10%,H25*(-0.02), IF(K25 >= -15%,H25*(-0.03), IF(K25 >= -20%,H25*(-0.04), IF(K25 >= -25%,H25*(-0.05), IF(K25 >= -30%,H25*(-0.06), IF(K25 >= -35%,H25*(-0.07), IF(K25 >= -40%,H25*(-0.08), IF(K25 >= -45%,H25*(-0.09), IF(K25 >= -50%, H25*(-0.1), H25* 0) )))))))))),"") | N25: =IF(NOT(ISNUMBER(H25)),"",IF(M25="Kein Balkon",H25*(-0.05),H25*0)) | P25: =IF(NOT(ISNUMBER(H25)),"",IF(ISBLANK(O25),0,H25*MIN((YEAR(TODAY())-O25)*0.003,0.09)*-1)) | R25: =IF(ISNUMBER(MIETER!F27),IF(Q25="renoviert",H25*0.05,IF(Q25="teilweise renoviert",H25*0,IF(Q25="unrenoviert",H25*-0.05,0))),"") | S25: =IF(ISNUMBER(MIETER!F27),C25,"") | T25: =IF(ISNUMBER(MIETER!F27),IF(OR(S25="EG",S25="1.OG",S25="2.OG",S25="OG",S25="über 2.OG mit Aufzug"),H25*0,IF(OR(S25="UG",S25="über 2.OG ohne Aufzug"),H25*(-0.05),0)),"") | U25: =IF(ISNUMBER(MIETER!F27),IFERROR(F25*(H25+J25+L25+N25+P25+R25+T25),""),"") | V25: =IF(NOT(ISNUMBER(MIETER!F27)),"",N('Verkauf Cashflow'!Q22)+N('Verkauf Cashflow'!R22)) | W25: =IF(ISNUMBER(MIETER!F27),U25+V25,"") | X25: =IF(ISNUMBER('Verkauf Cashflow'!O22),'Verkauf Cashflow'!O22,"") | Y25: =IF(ISNUMBER('Verkauf Cashflow'!S22),'Verkauf Cashflow'!S22,"") | Z25: =IF(ISNUMBER(MIETER!F27),IFERROR(Y25/F25,""),"") | AA25: =IF(ISNUMBER('Verkauf Cashflow'!CF22),'Verkauf Cashflow'!CF22,"")
C26: Rücklage
C27: Subventionskosten
C28: Summe | F28: =SUM(F6:F25) | G28: =AVERAGEIF(G6:G25, ">0") | H28: =AVERAGEIF(H6:H25, ">0") | U28: =SUM(U6:U25) | V28: =SUM(V6:V25) | W28: =SUM(W6:W25) | X28: =SUM(X6:X25) | Y28: =SUM(Y6:Y27) | Z28: =IFERROR(AVERAGEIF(Z6:Z25, ">0"),"") | AA28: =IFERROR(AVERAGE(AA6:AA25),"")

Sheet Verkauf Cashflow
A1: STAMM | L1: PREIS | AG1: MIETE | AW1: BEWIRTSCHAFTUNG | BE1: STEUER | BS1: ERGEBNIS
A2: WE | B2: Haus | C2: WHG | D2: Etage | E2: Lage | F2: Wohnfläche m2 | G2: Leer- stand | H2: Gar. Anz. | I2: Stpl. Anz. | J2: MEA Zähler | K2: MEA- Anteil | L2: REGLER Abgabe €/m² | M2: Markt €/m² | N2: Delta zu Markt | O2: Indiv. Auf-/ Abschlag € | P2: Abgabepreis Wohnung | Q2: Abgabepreis Garage | R2: Abgabepreis Stellplatz | S2: Abgabepreis gesamt | T2: Provision % (leer=Std.) | U2: Provision effektiv | V2: Provision EUR | W2: Kaufpreis gesamt | X2: Kaufpreis Wohnung | Y2: Abgabe ges. €/m² (CRM) | Z2: Kaufpreis Whg €/m² | AA2: Beurkundeter KP Wohnung | AB2: Kauf- nebenkosten | AC2: Kapital- bedarf | AD2: Darlehen (Annahme C12) | AE2: Eigen- kapital | AF2: Aufschlag Beurkundung | AG2: Kaltmiete manuell €/Mo | AH2: Kaltmiete IST €/Mo | AI2: Soll-/Zielmiete €/Mo | AJ2: Subvention Tag 1 €/Mo | AK2: Subvention Ø Modul 5 €/Mo | AL2: Miete Garage | AM2: Miete Stellplatz | AN2: Miete gesamt ohne Subv. | AO2: Einnahmen CF (inkl. Subv.) | AP2: Kaltmiete €/m² | AQ2: letzte Erhöhung | AR2: nächste Erhöhung ab | AS2: Reach-Time Mo (Modul 5) | AT2: Rest- monate | AU2: Subvention gesamt € | AV2: Soll-Vorschlag 2 Kappungen | AW2: Bewirt. % (Schaetzung) | AX2: Hausgeld n.u. (leer=Std.) | AY2: Hausgeld n.u. €/Mo | AZ2: davon Rücklage (leer=Std.) | BA2: davon Rücklage €/Mo | BB2: Bewirt.quote % v. NKM IST | BC2: 1 % Bewirt. €/Mo v. NKM | BD2: 1 %-Pkt Bewirt. = € Kaufpreis | BE2: Bodenwert WE € | BF2: Gebäudeanteil lt. Vertrag | BG2: Gebäudeanteil aus BRW (100 %) | BH2: Gebäudeanteil effektiv (Quote) | BI2: Anteil- Quelle | BJ2: AfA-Satz WE (leer=C9) | BK2: AfA-Satz effektiv | BL2: AfA-Basis Wohnung | BM2: AfA €/Mo | BN2: Zinsen €/Mo | BO2: Annuitaet €/Mo | BP2: Steuerbasis €/Mo | BQ2: Erstattung (+) Steuer (-) | BR2: Rücklage spaeter abziehbar €/Mo | BS2: CF vor Steuern €/Mo | BT2: CF nach Steuern €/Mo | BU2: CF n.St. ohne Subvention | BV2: Rechenhilfe: Ertrag n.St. o. Fin. | BW2: Rechenhilfe: Garage/Stpl. netto 100 % | BX2: Rechenhilfe: k bei 100 % | BY2: Rechenhilfe: k bei 109,3 % | BZ2: max. tragbar KP Wohnung 100 % | CA2: max. tragbar KP Wohnung 109,3 % | CB2: max. tragbar 109,3 % OHNE Subvention | CC2: max. tragbar Regler €/m² | CD2: Delta Regler zu max. tragbar | CE2: Faktor | CF2: Brutto- mietrendite | CG2: Ampel Fall 100 % KP | CH2: Ampel Fall 109,3 %
